Workbook

Sheet DGA
A1: S. No. | B1: DGA Analysis (IS 10593,9434) test value in ppm (Parts-per-million) | Q1: Rogers Ratio Method | W1: IEC Ratio Method | AC1: Dornenburg Ratio Method
B2: SR. NO. | C2: Rating | D2: Ratio(KV) | E2: Make | F2: Year of Manufacture | G2: TGC Total Gas Content | H2: H2 Hydrogen | I2: O2 Oxygen | J2: N2 Nitrogen | K2: CO Carbomonoxide | L2: CO2 Carbondioxide | M2: CH4 Methane | N2: C2H6 Ethane | O2: C2H4 Ethylene | P2: C2H2 Acetyline | Q2: C2H2/C2H4 | R2: CH4/H2 | S2: C2H4/C2H6 | T2: FAULT TYPE | W2: C2H2/C2H4 | X2: CH4/H2 | Y2: C2H4/C2H6 | Z2: FAULT TYPE | AC2: CH4/H2 | AD2: C2H2/C2H4 | AE2: C2H2/CH4 | AF2: C2H6/C2H2 | AG2: FAULT TYPE
A3: 1 | B3: HT-1869/13207 | C3: 50 MVA | D3: 66/0.433 KV | E3: EMCO | F3: 2010 | G3: 8.4 | H3: 1.176 | I3: 15746.136 | J3: 65474.976 | K3: 153.636 | L3: 1468.488 | M3: 1.008 | N3: 2 | O3: 1 | P3: 3 | Q3: =IFERROR(P3/O3," ") -> 3 | R3: =M3/H3 -> 0.8571428571 | S3: 0.5 | T3: Arching | U3: Arching,Low temprature thermal fault | V3: Arching,Thermal Fault > 700 c | W3: =P3/O3 -> 3 | X3: =M3/H3 -> 0.8571428571 | Y3: 0.5 | Z3: Thermal Faults>700c | AA3: High Energy Discharge | AB3: thermal fault <300 | AC3: =M3/H3 -> 0.8571428571 | AD3: 3 | AE3: =P3/M3 -> 2.976190476 | AF3: 0.6 | AG3: Arching | AH3: Arching | AI3: Arching | AJ3: =IF(AF3>0.4,"Thermal Decomposition,corona ",IF(AF3<0.4,"Arching")) -> Thermal Decomposition,corona
A4: 2 | B4: HT-1869/13207 | C4: 50 MVA | D4: 66/0.433 KV | E4: EMCO | F4: 2010 | G4: 8.6 | H4: 954.17 | I4: 15964.868 | J4: 65313.904 | K4: 44.806 | L4: 568.546 | M4: 118.594 | N4: 27.09 | O4: 816.57 | P4: 1077.15 | Q4: =IFERROR(P4/O4," ") -> 1.319115324 | R4: =M4/H4 -> 0.1242902208 | S4: =IFERROR(O4/N4," ") -> 30.14285714 | T4: Arching | U4: Arching,Low temprature thermal fault | V4: =IF(S4<1,"Partial discharge, Normal ",IF(S4>3,"Arching,Thermal Fault > 700 c")) -> Arching,Thermal Fault > 700 c | W4: =P4/O4 -> 1.319115324 | X4: =M4/H4 -> 0.1242902208 | Y4: =IFERROR(O4/N4," ") -> 30.14285714 | Z4: High Energy Discharge | AA4: High Energy Discharge | AB4: Thermal Fault >700 c | AC4: =M4/H4 -> 0.1242902208 | AD4: =IFERROR(P4/O4," ") -> 1.319115324 | AE4: =P4/M4 -> 9.0826686 | AF4: =IFERROR(N4/P4," ") -> 0.0251497006 | AG4: Arching | AH4: =IF(AD4<0.75,"Thermal Decomposition, ",IF(AD4>0.75,"Arching")) -> Arching | AI4: =IF(AE4<0.3,"Thermal Decomposition,corona ",IF(AE4>0.3,"Arching")) -> Arching | AJ4: =IF(AF4>0.4,"Thermal Decomposition,corona ",IF(AF4<0.4,"Arching")) -> Arching
A5: 3 | B5: HT-1869/13207 | C5: 50 MVA | D5: 66/0.433 KV | E5: EMCO | F5: 2010 | G5: 8.4 | H5: 2.94 | I5: 15616.86 | J5: 65702.784 | K5: 161.364 | L5: 1648.248 | M5: 7 | N5: 9 | O5: 11 | P5: 9 | Q5: =IFERROR(P5/O5," ") -> 0.8181818182 | R5: =M5/H5 -> 2.380952381 | S5: =IFERROR(O5/N5," ") -> 1.222222222 | T5: Arching | U5: Arching | V5: Low Temprature thermal Fault,Thermal Fault<700c | W5: =P5/O5 -> 0.8181818182 | X5: =M5/H5 -> 2.380952381 | Y5: =IFERROR(O5/N5," ") -> 1.222222222 | Z5: High Energy Discharge | AA5: =IF(X5<0.1,"Partial Discharges, ",IF(X5>1,"Thermal Fault >300c and<700 and >700 c")) -> Thermal Fault >300c and<700 and >700 c | AB5: =IF(Y5<0.2,"Partial Discharges, ",IF(Y5>1,"Thermal Fault >700 c")) -> Thermal Fault >700 c | AC5: =M5/H5 -> 2.380952381 | AD5: =IFERROR(P5/O5," ") -> 0.8181818182 | AE5: =P5/M5 -> 1.285714286 | AF5: =IFERROR(N5/P5," ") -> 1 | AG5: Thermal Decomposition | AH5: =IF(AD5<0.75,"Thermal Decomposition, ",IF(AD5>0.75,"Arching")) -> Arching | AI5: =IF(AE5<0.3,"Thermal Decomposition,corona ",IF(AE5>0.3,"Arching")) -> Arching | AJ5: =IF(AF5>0.4,"Thermal Decomposition,corona ",IF(AF5<0.4,"Arching")) -> Thermal Decomposition,corona
A6: 4 | B6: B-22806(DIT-000055) | C6: 10 MVA | D6: 33/11 KV | E6: THE GENERAL ELECTRICAL | F6: 1982 | G6: 8.2 | H6: 9.348 | I6: 15345.89 | J6: 63123.928 | K6: 196.226 | L6: 2272.466 | M6: 6 | N6: 2.46 | O6: 38.048 | P6: 23 | Q6: =IFERROR(P6/O6," ") -> 0.6044995795 | R6: =M6/H6 -> 0.6418485237 | S6: =IFERROR(O6/N6," ") -> 15.46666667 | T6: Arching | U6: Arching,Low temprature thermal fault | V6: =IF(S6<1,"Partial discharge, Normal ",IF(S6>3,"Arching,Thermal Fault > 700 c")) -> Arching,Thermal Fault > 700 c | W6: =P6/O6 -> 0.6044995795 | X6: =M6/H6 -> 0.6418485237 | Y6: =IFERROR(O6/N6," ") -> 15.46666667 | Z6: High Energy Discharge | AA6: High Energy Discharge | AB6: =IF(Y6<0.2,"Partial Discharges, ",IF(Y6>1,"Thermal Fault >700 c")) -> Thermal Fault >700 c | AC6: =M6/H6 -> 0.6418485237 | AD6: =IFERROR(P6/O6," ") -> 0.6044995795 | AE6: =P6/M6 -> 3.833333333 | AF6: =IFERROR(N6/P6," ") -> 0.1069565217 | AG6: Arching | AH6: =IF(AD6<0.75,"Thermal Decomposition, ",IF(AD6>0.75,"Arching")) -> Thermal Decomposition, | AI6: Arching | AJ6: =IF(AF6>0.4,"Thermal Decomposition,corona ",IF(AF6<0.4,"Arching")) -> Arching
A7: 5 | B7: 1000060003(DIT-000026) | C7: 10 MVA | D7: 33/11 KV | E7: PME | F7: 2005 | G7: 7.8 | H7: 4.758 | I7: 14397.006 | J7: 60962.226 | K7: 179.712 | L7: 1573.494 | M7: 2.184 | N7: 6.162 | O7: 8.658 | P7: 12 | Q7: =IFERROR(P7/O7," ") -> 1.386001386 | R7: =M7/H7 -> 0.4590163934 | S7: =IFERROR(O7/N7," ") -> 1.405063291 | T7: Arching | U7: Arching,Low temprature thermal fault | V7: Low Temprature thermal Fault,Thermal Fault<700c | W7: =P7/O7 -> 1.386001386 | X7: =M7/H7 -> 0.4590163934 | Y7: =IFERROR(O7/N7," ") -> 1.405063291 | Z7: =IF(W7>1,"Discharge of Low Energy, ",IF(W7<0.1,"Thermal Fault> 300c and<700 c")) -> Discharge of Low Energy, | AA7: High Energy Discharge | AB7: =IF(Y7<0.2,"Partial Discharges, ",IF(Y7>1,"Thermal Fault >700 c")) -> Thermal Fault >700 c | AC7: =M7/H7 -> 0.4590163934 | AD7: =IFERROR(P7/O7," ") -> 1.386001386 | AE7: =P7/M7 -> 5.494505495 | AF7: =IFERROR(N7/P7," ") -> 0.5135 | AG7: Arching | AH7: =IF(AD7<0.75,"Thermal Decomposition, ",IF(AD7>0.75,"Arching")) -> Arching | AI7: =IF(AE7<0.3,"Thermal Decomposition,corona ",IF(AE7>0.3,"Arching")) -> Arching | AJ7: =IF(AF7>0.4,"Thermal Decomposition,corona ",IF(AF7<0.4,"Arching")) -> Thermal Decomposition,corona
A8: 6 | B8: 172580(DIT-000090) | C8: 10 MVA | D8: 33/11 KV | E8: RAJASTAN | F8: 2006 | G8: 8.2 | H8: 5.904 | I8: 15182.956 | J8: 63176.162 | K8: 223.532 | L8: 2445.486 | M8: 13.038 | N8: 57.236 | O8: 18.204 | P8: 34 | Q8: =IFERROR(P8/O8," ") -> 1.86772138 | R8: =M8/H8 -> 2.208333333 | S8: =IFERROR(O8/N8," ") -> 0.3180515759 | T8: Arching | U8: =IF(R8>1,"Thermal Fault <700c, thermal fault >700c ") -> Thermal Fault <700c, thermal fault >700c | V8: =IF(S8<1,"Partial discharge, Normal ",IF(S8>3,"Arching,Thermal Fault > 700 c")) -> Partial discharge, Normal | W8: =P8/O8 -> 1.86772138 | X8: =M8/H8 -> 2.208333333 | Y8: =IFERROR(O8/N8," ") -> 0.3180515759 | Z8: =IF(W8>1,"Discharge of Low Energy, ",IF(W8<0.1,"Thermal Fault> 300c and<700 c")) -> Discharge of Low Energy, | AA8: High Energy Discharge | AB8: thermal fault <300 | AC8: =M8/H8 -> 2.208333333 | AD8: =IFERROR(P8/O8," ") -> 1.86772138 | AE8: =P8/M8 -> 2.607761927 | AF8: =IFERROR(N8/P8," ") -> 1.683411765 | AG8: Thermal Decomposition | AH8: =IF(AD8<0.75,"Thermal Decomposition, ",IF(AD8>0.75,"Arching")) -> Arching | AI8: =IF(AE8<0.3,"Thermal Decomposition,corona ",IF(AE8>0.3,"Arching")) -> Arching | AJ8: =IF(AF8>0.4,"Thermal Decomposition,corona ",IF(AF8<0.4,"Arching")) -> Thermal Decomposition,corona
A9: 7 | B9: 10000000021 T-2204 | C9: 10 MVA | D9: 33/11 KV | E9: PME | F9: 2003 | G9: 8.4 | H9: 7.476 | I9: 15497.244 | J9: 65034.312 | K9: 195.048 | L9: 2150.904 | M9: 13.02 | N9: 111.3 | O9: 27.3 | P9: 43 | Q9: =IFERROR(P9/O9," ") -> 1.575091575 | R9: =M9/H9 -> 1.741573034 | S9: =IFERROR(O9/N9," ") -> 0.2452830189 | T9: Arching | U9: =IF(R9>1,"Thermal Fault <700c, thermal fault >700c ") -> Thermal Fault <700c, thermal fault >700c | V9: =IF(S9<1,"Partial discharge, Normal ",IF(S9>3,"Arching,Thermal Fault > 700 c")) -> Partial discharge, Normal | W9: =P9/O9 -> 1.575091575 | X9: =M9/H9 -> 1.741573034 | Y9: =IFERROR(O9/N9," ") -> 0.2452830189 | Z9: =IF(W9>1,"Discharge of Low Energy, ",IF(W9<0.1,"Thermal Fault> 300c and<700 c")) -> Discharge of Low Energy, | AA9: thermal fault<300 | AB9: thermal fault <300 | AC9: =M9/H9 -> 1.741573034 | AD9: =IFERROR(P9/O9," ") -> 1.575091575 | AE9: =P9/M9 -> 3.302611367 | AF9: =IFERROR(N9/P9," ") -> 2.588372093 | AG9: =IF(AC9>1,"Thermal Decomposition, ",IF(AC9<0.1,"Corona,Arching")) -> Thermal Decomposition, | AH9: =IF(AD9<0.75,"Thermal Decomposition, ",IF(AD9>0.75,"Arching")) -> Arching | AI9: =IF(AE9<0.3,"Thermal Decomposition,corona ",IF(AE9>0.3,"Arching")) -> Arching | AJ9: =IF(AF9>0.4,"Thermal Decomposition,corona ",IF(AF9<0.4,"Arching")) -> Thermal Decomposition,corona
A10: 8 | B10: 172578 | C10: 10 MVA | D10: 33/11 KV | E10: RAJASTAN | F10: 2006 | G10: 8.6 | H10: 5.332 | I10: 15666.792 | J10: 66793.018 | K10: 190.662 | L10: 2283.3 | M10: 2.15 | N10: 13.33 | O10: 5.59 | P10: 10 | Q10: =IFERROR(P10/O10," ") -> 1.788908766 | R10: =M10/H10 -> 0.4032258065 | S10: =IFERROR(O10/N10," ") -> 0.4193548387 | T10: Arching | U10: Arching,Low temprature thermal fault | V10: =IF(S10<1,"Partial discharge, Normal ",IF(S10>3,"Arching,Thermal Fault > 700 c")) -> Partial discharge, Normal | W10: =P10/O10 -> 1.788908766 | X10: =M10/H10 -> 0.4032258065 | Y10: =IFERROR(O10/N10," ") -> 0.4193548387 | Z10: =IF(W10>1,"Discharge of Low Energy, ",IF(W10<0.1,"Thermal Fault> 300c and<700 c")) -> Discharge of Low Energy, | AA10: High Energy Discharge | AB10: thermal fault <300 | AC10: =M10/H10 -> 0.4032258065 | AD10: =IFERROR(P10/O10," ") -> 1.788908766 | AE10: =P10/M10 -> 4.651162791 | AF10: =IFERROR(N10/P10," ") -> 1.333 | AG10: Arching | AH10: =IF(AD10<0.75,"Thermal Decomposition, ",IF(AD10>0.75,"Arching")) -> Arching | AI10: =IF(AE10<0.3,"Thermal Decomposition,corona ",IF(AE10>0.3,"Arching")) -> Arching | AJ10: =IF(AF10>0.4,"Thermal Decomposition,corona ",IF(AF10<0.4,"Arching")) -> Thermal Decomposition,corona
A11: 9 | B11: TTL/UP25235 T-1960 | C11: 10 MVA | D11: 33/11 | E11: TESLA TRANSFORMER | F11: 2002 | G11: 7.8 | H11: 7.488 | I11: 14384.994 | J11: 59960.238 | K11: 269.334 | L11: 2765.334 | M11: 18.954 | N11: 7.722 | O11: 31.122 | P11: 25 | Q11: =IFERROR(P11/O11," ") -> 0.803290277 | R11: =M11/H11 -> 2.53125 | S11: =IFERROR(O11/N11," ") -> 4.03030303 | T11: =IF(Q11<1,"Partial discharge,Low Temprature thermal fault,") -> Partial discharge,Low Temprature thermal fault, | U11: =IF(R11>1,"Thermal Fault <700c, thermal fault >700c ") -> Thermal Fault <700c, thermal fault >700c | V11: =IF(S11<1,"Partial discharge, Normal ",IF(S11>3,"Arching,Thermal Fault > 700 c")) -> Arching,Thermal Fault > 700 c | W11: =P11/O11 -> 0.803290277 | X11: =M11/H11 -> 2.53125 | Y11: =IFERROR(O11/N11," ") -> 4.03030303 | Z11: High Energy Discharge | AA11: =IF(X11<0.1,"Partial Discharges, ",IF(X11>1,"Thermal Fault >300c and<700 and >700 c")) -> Thermal Fault >300c and<700 and >700 c | AB11: =IF(Y11<0.2,"Partial Discharges, ",IF(Y11>1,"Thermal Fault >700 c")) -> Thermal Fault >700 c | AC11: =M11/H11 -> 2.53125 | AD11: =IFERROR(P11/O11," ") -> 0.803290277 | AE11: =P11/M11 -> 1.3189828 | AF11: =IFERROR(N11/P11," ") -> 0.30888 | AG11: =IF(AC11>1,"Thermal Decomposition, ",IF(AC11<0.1,"Corona,Arching")) -> Thermal Decomposition, | AH11: =IF(AD11<0.75,"Thermal Decomposition, ",IF(AD11>0.75,"Arching")) -> Arching | AI11: =IF(AE11<0.3,"Thermal Decomposition,corona ",IF(AE11>0.3,"Arching")) -> Arching | AJ11: =IF(AF11>0.4,"Thermal Decomposition,corona ",IF(AF11<0.4,"Arching")) -> Arching
A12: 10 | B12: 69546 | C12: 10 MVA | D12: 33/11 KV | E12: MARSONS | F12: 2012 | G12: 8.1 | H12: 5.589 | I12: 15002.739 | J12: 61258.113 | K12: 353.808 | L12: 3861.837 | M12: 7.371 | N12: 6 | O12: 4 | P12: 8 | Q12: =IFERROR(P12/O12," ") -> 2 | R12: =M12/H12 -> 1.31884058 | S12: =IFERROR(O12/N12," ") -> 0.6666666667 | T12: Arching | U12: =IF(R12>1,"Thermal Fault <700c, thermal fault >700c ") -> Thermal Fault <700c, thermal fault >700c | V12: =IF(S12<1,"Partial discharge, Normal ",IF(S12>3,"Arching,Thermal Fault > 700 c")) -> Partial discharge, Normal | W12: =P12/O12 -> 2 | X12: =M12/H12 -> 1.31884058 | Y12: =IFERROR(O12/N12," ") -> 0.6666666667 | Z12: =IF(W12>1,"Discharge of Low Energy, ",IF(W12<0.1,"Thermal Fault> 300c and<700 c")) -> Discharge of Low Energy, | AA12: =IF(X12<0.1,"Partial Discharges, ",IF(X12>1,"Thermal Fault >300c and<700 and >700 c")) -> Thermal Fault >300c and<700 and >700 c | AB12: thermal fault <300 | AC12: =M12/H12 -> 1.31884058 | AD12: =IFERROR(P12/O12," ") -> 2 | AE12: =P12/M12 -> 1.085334419 | AF12: =IFERROR(N12/P12," ") -> 0.75 | AG12: =IF(AC12>1,"Thermal Decomposition, ",IF(AC12<0.1,"Corona,Arching")) -> Thermal Decomposition, | AH12: =IF(AD12<0.75,"Thermal Decomposition, ",IF(AD12>0.75,"Arching")) -> Arching | AI12: =IF(AE12<0.3,"Thermal Decomposition,corona ",IF(AE12>0.3,"Arching")) -> Arching | AJ12: =IF(AF12>0.4,"Thermal Decomposition,corona ",IF(AF12<0.4,"Arching")) -> Thermal Decomposition,corona
A13: 11 | B13: 69543 | C13: 10 MVA | D13: 33/11 KV | E13: MARSONS | F13: 2011 | G13: 8.5 | H13: 1.615 | I13: 15602.43 | J13: 65923.28 | K13: 211.905 | L13: 2347.105 | M13: 5.525 | N13: 5 | O13: 5 | P13: 4 | Q13: =IFERROR(P13/O13," ") -> 0.8 | R13: =M13/H13 -> 3.421052632 | S13: =IFERROR(O13/N13," ") -> 1 | T13: =IF(Q13<1,"Partial discharge,Low Temprature thermal fault,") -> Partial discharge,Low Temprature thermal fault, | U13: =IF(R13>1,"Thermal Fault <700c, thermal fault >700c ") -> Thermal Fault <700c, thermal fault >700c | V13: Low Temprature thermal Fault,Thermal Fault<700c | W13: =P13/O13 -> 0.8 | X13: =M13/H13 -> 3.421052632 | Y13: =IFERROR(O13/N13," ") -> 1 | Z13: High Energy Discharge | AA13: =IF(X13<0.1,"Partial Discharges, ",IF(X13>1,"Thermal Fault >300c and<700 and >700 c")) -> Thermal Fault >300c and<700 and >700 c | AB13: High energhy Discharge | AC13: =M13/H13 -> 3.421052632 | AD13: =IFERROR(P13/O13," ") -> 0.8 | AE13: =P13/M13 -> 0.7239819005 | AF13: =IFERROR(N13/P13," ") -> 1.25 | AG13: =IF(AC13>1,"Thermal Decomposition, ",IF(AC13<0.1,"Corona,Arching")) -> Thermal Decomposition, | AH13: =IF(AD13<0.75,"Thermal Decomposition, ",IF(AD13>0.75,"Arching")) -> Arching | AI13: =IF(AE13<0.3,"Thermal Decomposition,corona ",IF(AE13>0.3,"Arching")) -> Arching | AJ13: =IF(AF13>0.4,"Thermal Decomposition,corona ",IF(AF13<0.4,"Arching")) -> Thermal Decomposition,corona
A14: 12 | B14: 69542 | C14: 10 MVA | D14: 33/11 KV | E14: MARSONS | F14: 2011 | G14: 8.4 | H14: 8.064 | I14: 15280.356 | J14: 64058.484 | K14: 396.564 | L14: 3724.728 | M14: 11.34 | N14: 10 | O14: 10 | P14: 8 | Q14: =IFERROR(P14/O14," ") -> 0.8 | R14: =M14/H14 -> 1.40625 | S14: =IFERROR(O14/N14," ") -> 1 | T14: =IF(Q14<1,"Partial discharge,Low Temprature thermal fault,") -> Partial discharge,Low Temprature thermal fault, | U14: =IF(R14>1,"Thermal Fault <700c, thermal fault >700c ") -> Thermal Fault <700c, thermal fault >700c | V14: Low Temprature thermal Fault,Thermal Fault<700c | W14: =P14/O14 -> 0.8 | X14: =M14/H14 -> 1.40625 | Y14: =IFERROR(O14/N14," ") -> 1 | Z14: High Energy Discharge | AA14: =IF(X14<0.1,"Partial Discharges, ",IF(X14>1,"Thermal Fault >300c and<700 and >700 c")) -> Thermal Fault >300c and<700 and >700 c | AB14: High energhy Discharge | AC14: =M14/H14 -> 1.40625 | AD14: =IFERROR(P14/O14," ") -> 0.8 | AE14: =P14/M14 -> 0.7054673721 | AF14: =IFERROR(N14/P14," ") -> 1.25 | AG14: =IF(AC14>1,"Thermal Decomposition, ",IF(AC14<0.1,"Corona,Arching")) -> Thermal Decomposition, | AH14: =IF(AD14<0.75,"Thermal Decomposition, ",IF(AD14>0.75,"Arching")) -> Arching | AI14: =IF(AE14<0.3,"Thermal Decomposition,corona ",IF(AE14>0.3,"Arching")) -> Arching | AJ14: =IF(AF14>0.4,"Thermal Decomposition,corona ",IF(AF14<0.4,"Arching")) -> Thermal Decomposition,corona
A15: 13 | B15: 69545 | C15: 10 MVA | D15: 33/11 KV | E15: MARSONS | F15: 2012 | G15: 8.2 | H15: 3.69 | I15: 15127.688 | J15: 64168.772 | K15: 174.086 | L15: 2084.85 | M15: 5.33 | N15: 4.018 | O15: 8.856 | P15: 8 | Q15: =IFERROR(P15/O15," ") -> 0.9033423668 | R15: =M15/H15 -> 1.444444444 | S15: =IFERROR(O15/N15," ") -> 2.204081633 | T15: =IF(Q15<1,"Partial discharge,Low Temprature thermal fault,") -> Partial discharge,Low Temprature thermal fault, | U15: =IF(R15>1,"Thermal Fault <700c, thermal fault >700c ") -> Thermal Fault <700c, thermal fault >700c | V15: Low Temprature thermal Fault,Thermal Fault<700c | W15: =P15/O15 -> 0.9033423668 | X15: =M15/H15 -> 1.444444444 | Y15: =IFERROR(O15/N15," ") -> 2.204081633 | Z15: High Energy Discharge | AA15: =IF(X15<0.1,"Partial Discharges, ",IF(X15>1,"Thermal Fault >300c and<700 and >700 c")) -> Thermal Fault >300c and<700 and >700 c | AB15: =IF(Y15<0.2,"Partial Discharges, ",IF(Y15>1,"Thermal Fault >700 c")) -> Thermal Fault >700 c | AC15: =M15/H15 -> 1.444444444 | AD15: =IFERROR(P15/O15," ") -> 0.9033423668 | AE15: =P15/M15 -> 1.500938086 | AF15: =IFERROR(N15/P15," ") -> 0.50225 | AG15: =IF(AC15>1,"Thermal Decomposition, ",IF(AC15<0.1,"Corona,Arching")) -> Thermal Decomposition, | AH15: =IF(AD15<0.75,"Thermal Decomposition, ",IF(AD15>0.75,"Arching")) -> Arching | AI15: =IF(AE15<0.3,"Thermal Decomposition,corona ",IF(AE15>0.3,"Arching")) -> Arching | AJ15: =IF(AF15>0.4,"Thermal Decomposition,corona ",IF(AF15<0.4,"Arching")) -> Thermal Decomposition,corona
A16: 14 | B16: ATL-10187070001 | C16: 10 MVA | D16: 33/11 KV | E16: ACCURATE | F16: 2008 | G16: 8.4 | H16: 5.124 | I16: 15196.272 | J16: 65697.072 | K16: 185.304 | L16: 2039.604 | M16: 2.94 | N16: 2.1 | O16: 5.796 | P16: 5 | Q16: =IFERROR(P16/O16," ") -> 0.8626639061 | R16: =M16/H16 -> 0.5737704918 | S16: =IFERROR(O16/N16," ") -> 2.76 | T16: =IF(Q16<1,"Partial discharge,Low Temprature thermal fault,") -> Partial discharge,Low Temprature thermal fault, | U16: Arching,Low temprature thermal fault | V16: Low Temprature thermal Fault,Thermal Fault<700c | W16: =P16/O16 -> 0.8626639061 | X16: =M16/H16 -> 0.5737704918 | Y16: =IFERROR(O16/N16," ") -> 2.76 | Z16: High Energy Discharge | AA16: High Energy Discharge | AB16: =IF(Y16<0.2,"Partial Discharges, ",IF(Y16>1,"Thermal Fault >700 c")) -> Thermal Fault >700 c | AC16: =M16/H16 -> 0.5737704918 | AD16: =IFERROR(P16/O16," ") -> 0.8626639061 | AE16: =P16/M16 -> 1.700680272 | AF16: =IFERROR(N16/P16," ") -> 0.42 | AG16: Arching | AH16: =IF(AD16<0.75,"Thermal Decomposition, ",IF(AD16>0.75,"Arching")) -> Arching | AI16: =IF(AE16<0.3,"Thermal Decomposition,corona ",IF(AE16>0.3,"Arching")) -> Arching | AJ16: =IF(AF16>0.4,"Thermal Decomposition,corona ",IF(AF16<0.4,"Arching")) -> Thermal Decomposition,corona
A17: 15 | B17: 2165 | C17: 10 MVA | D17: 33/11 KV | E17: PARTICULAR | F17: 2013 | G17: 8.5 | H17: 8.415 | I17: 15522.955 | J17: 65567.385 | K17: 233.58 | L17: 2540.48 | M17: 7.225 | N17: 9 | O17: 8 | P17: 8 | Q17: =IFERROR(P17/O17," ") -> 1 | R17: =M17/H17 -> 0.8585858586 | S17: =IFERROR(O17/N17," ") -> 0.8888888889 | T17: Arching | U17: Arching,Low temprature thermal fault | V17: =IF(S17<1,"Partial discharge, Normal ",IF(S17>3,"Arching,Thermal Fault > 700 c")) -> Partial discharge, Normal | W17: =P17/O17 -> 1 | X17: =M17/H17 -> 0.8585858586 | Y17: =IFERROR(O17/N17," ") -> 0.8888888889 | Z17: High Energy Discharge | AA17: High Energy Discharge | AB17: High energhy Discharge | AC17: =M17/H17 -> 0.8585858586 | AD17: =IFERROR(P17/O17," ") -> 1 | AE17: =P17/M17 -> 1.107266436 | AF17: =IFERROR(N17/P17," ") -> 1.125 | AG17: Arching | AH17: =IF(AD17<0.75,"Thermal Decomposition, ",IF(AD17>0.75,"Arching")) -> Arching | AI17: =IF(AE17<0.3,"Thermal Decomposition,corona ",IF(AE17>0.3,"Arching")) -> Arching | AJ17: =IF(AF17>0.4,"Thermal Decomposition,corona ",IF(AF17<0.4,"Arching")) -> Thermal Decomposition,corona
A18: 16 | B18: 95589 | C18: 10 MVA | D18: 33/11 KV | E18: MARSONS | F18: 2015 | G18: 8 | H18: 9.52 | I18: 14900.96 | J18: 60161.52 | K18: 387.84 | L18: 3842.96 | M18: 18.32 | N18: 4.08 | O18: 11.84 | P18: 18 | Q18: =IFERROR(P18/O18," ") -> 1.52027027 | R18: =M18/H18 -> 1.924369748 | S18: =IFERROR(O18/N18," ") -> 2.901960784 | T18: Arching | U18: =IF(R18>1,"Thermal Fault <700c, thermal fault >700c ") -> Thermal Fault <700c, thermal fault >700c | V18: Low Temprature thermal Fault,Thermal Fault<700c | W18: =P18/O18 -> 1.52027027 | X18: =M18/H18 -> 1.924369748 | Y18: =IFERROR(O18/N18," ") -> 2.901960784 | Z18: =IF(W18>1,"Discharge of Low Energy, ",IF(W18<0.1,"Thermal Fault> 300c and<700 c")) -> Discharge of Low Energy, | AA18: =IF(X18<0.1,"Partial Discharges, ",IF(X18>1,"Thermal Fault >300c and<700 and >700 c")) -> Thermal Fault >300c and<700 and >700 c | AB18: =IF(Y18<0.2,"Partial Discharges, ",IF(Y18>1,"Thermal Fault >700 c")) -> Thermal Fault >700 c | AC18: =M18/H18 -> 1.924369748 | AD18: =IFERROR(P18/O18," ") -> 1.52027027 | AE18: =P18/M18 -> 0.9825327511 | AF18: =IFERROR(N18/P18," ") -> 0.2266666667 | AG18: =IF(AC18>1,"Thermal Decomposition, ",IF(AC18<0.1,"Corona,Arching")) -> Thermal Decomposition, | AH18: =IF(AD18<0.75,"Thermal Decomposition, ",IF(AD18>0.75,"Arching")) -> Arching | AI18: =IF(AE18<0.3,"Thermal Decomposition,corona ",IF(AE18>0.3,"Arching")) -> Arching | AJ18: =IF(AF18>0.4,"Thermal Decomposition,corona ",IF(AF18<0.4,"Arching")) -> Arching
A19: 17 | B19: 62444 | C19: 10 MVA | D19: 33/11 KV | E19: MARSONS | F19: 2010 | G19: 8.5 | H19: 12.58 | I19: 16844.025 | J19: 60794.975 | K19: 603.33 | L19: 5941.755 | M19: 21.675 | N19: 16.065 | O19: 114.92 | P19: 100 | Q19: =IFERROR(P19/O19," ") -> 0.8701705534 | R19: =M19/H19 -> 1.722972973 | S19: =IFERROR(O19/N19," ") -> 7.153439153 | T19: =IF(Q19<1,"Partial discharge,Low Temprature thermal fault,") -> Partial discharge,Low Temprature thermal fault, | U19: =IF(R19>1,"Thermal Fault <700c, thermal fault >700c ") -> Thermal Fault <700c, thermal fault >700c | V19: =IF(S19<1,"Partial discharge, Normal ",IF(S19>3,"Arching,Thermal Fault > 700 c")) -> Arching,Thermal Fault > 700 c | W19: =P19/O19 -> 0.8701705534 | X19: =M19/H19 -> 1.722972973 | Y19: =IFERROR(O19/N19," ") -> 7.153439153 | Z19: High Energy Discharge | AA19: =IF(X19<0.1,"Partial Discharges, ",IF(X19>1,"Thermal Fault >300c and<700 and >700 c")) -> Thermal Fault >300c and<700 and >700 c | AB19: =IF(Y19<0.2,"Partial Discharges, ",IF(Y19>1,"Thermal Fault >700 c")) -> Thermal Fault >700 c | AC19: =M19/H19 -> 1.722972973 | AD19: =IFERROR(P19/O19," ") -> 0.8701705534 | AE19: =P19/M19 -> 4.61361015 | AF19: =IFERROR(N19/P19," ") -> 0.16065 | AG19: =IF(AC19>1,"Thermal Decomposition, ",IF(AC19<0.1,"Corona,Arching")) -> Thermal Decomposition, | AH19: =IF(AD19<0.75,"Thermal Decomposition, ",IF(AD19>0.75,"Arching")) -> Arching | AI19: =IF(AE19<0.3,"Thermal Decomposition,corona ",IF(AE19>0.3,"Arching")) -> Arching | AJ19: =IF(AF19>0.4,"Thermal Decomposition,corona ",IF(AF19<0.4,"Arching")) -> Arching
A20: 18 | B20: T-2228 | C20: 10 MVA | D20: 33/11 KV | E20: KATSONS | F20: 2013 | G20: 8.2 | H20: 1.558 | I20: 14378.454 | J20: 65308.49 | K20: 134.726 | L20: 1422.618 | M20: 7.298 | N20: 11 | O20: 9 | P20: 6 | Q20: =IFERROR(P20/O20," ") -> 0.6666666667 | R20: =M20/H20 -> 4.684210526 | S20: =IFERROR(O20/N20," ") -> 0.8181818182 | T20: =IF(Q20<1,"Partial discharge,Low Temprature thermal fault,") -> Partial discharge,Low Temprature thermal fault, | U20: =IF(R20>1,"Thermal Fault <700c, thermal fault >700c ") -> Thermal Fault <700c, thermal fault >700c | V20: =IF(S20<1,"Partial discharge, Normal ",IF(S20>3,"Arching,Thermal Fault > 700 c")) -> Partial discharge, Normal | W20: =P20/O20 -> 0.6666666667 | X20: =M20/H20 -> 4.684210526 | Y20: =IFERROR(O20/N20," ") -> 0.8181818182 | Z20: High Energy Discharge | AA20: =IF(X20<0.1,"Partial Discharges, ",IF(X20>1,"Thermal Fault >300c and<700 and >700 c")) -> Thermal Fault >300c and<700 and >700 c | AB20: High energhy Discharge | AC20: =M20/H20 -> 4.684210526 | AD20: =IFERROR(P20/O20," ") -> 0.6666666667 | AE20: =P20/M20 -> 0.8221430529 | AF20: =IFERROR(N20/P20," ") -> 1.833333333 | AG20: =IF(AC20>1,"Thermal Decomposition, ",IF(AC20<0.1,"Corona,Arching")) -> Thermal Decomposition, | AH20: =IF(AD20<0.75,"Thermal Decomposition, ",IF(AD20>0.75,"Arching")) -> Thermal Decomposition, | AI20: =IF(AE20<0.3,"Thermal Decomposition,corona ",IF(AE20>0.3,"Arching")) -> Arching | AJ20: =IF(AF20>0.4,"Thermal Decomposition,corona ",IF(AF20<0.4,"Arching")) -> Thermal Decomposition,corona
A21: 19 | B21: 103757 | C21: 10 MVA | D21: 33/11 KV | E21: MARSONS | F21: 2019 | G21: 8.2 | H21: 8.036 | I21: 14956.554 | J21: 64368.77 | K21: 168.592 | L21: 1772.102 | M21: 4.182 | N21: 15 | O21: 8 | P21: 8 | Q21: =IFERROR(P21/O21," ") -> 1 | R21: =M21/H21 -> 0.5204081633 | S21: =IFERROR(O21/N21," ") -> 0.5333333333 | T21: Arching | U21: Arching,Low temprature thermal fault | V21: =IF(S21<1,"Partial discharge, Normal ",IF(S21>3,"Arching,Thermal Fault > 700 c")) -> Partial discharge, Normal | W21: =P21/O21 -> 1 | X21: =M21/H21 -> 0.5204081633 | Y21: =IFERROR(O21/N21," ") -> 0.5333333333 | Z21: High Energy Discharge | AA21: High Energy Discharge | AB21: High energhy Discharge | AC21: =M21/H21 -> 0.5204081633 | AD21: =IFERROR(P21/O21," ") -> 1 | AE21: =P21/M21 -> 1.912960306 | AF21: =IFERROR(N21/P21," ") -> 1.875 | AG21: Arching | AH21: =IF(AD21<0.75,"Thermal Decomposition, ",IF(AD21>0.75,"Arching")) -> Arching | AI21: =IF(AE21<0.3,"Thermal Decomposition,corona ",IF(AE21>0.3,"Arching")) -> Arching | AJ21: =IF(AF21>0.4,"Thermal Decomposition,corona ",IF(AF21<0.4,"Arching")) -> Thermal Decomposition,corona
A22: 20 | B22: 102146 | C22: 10 MVA | D22: 33/11 KV | E22: MARSONS | F22: 2017 | G22: 8.5 | H22: 6.63 | I22: 15460.735 | J22: 65784.22 | K22: 249.305 | L22: 2536.06 | M22: 7.225 | N22: 9 | O22: 9 | P22: 3 | Q22: =IFERROR(P22/O22," ") -> 0.3333333333 | R22: =M22/H22 -> 1.08974359 | S22: =IFERROR(O22/N22," ") -> 1 | T22: =IF(Q22<1,"Partial discharge,Low Temprature thermal fault,") -> Partial discharge,Low Temprature thermal fault, | U22: =IF(R22>1,"Thermal Fault <700c, thermal fault >700c ") -> Thermal Fault <700c, thermal fault >700c | V22: Low Temprature thermal Fault,Thermal Fault<700c | W22: =P22/O22 -> 0.3333333333 | X22: =M22/H22 -> 1.08974359 | Y22: =IFERROR(O22/N22," ") -> 1 | Z22: High Energy Discharge | AA22: =IF(X22<0.1,"Partial Discharges, ",IF(X22>1,"Thermal Fault >300c and<700 and >700 c")) -> Thermal Fault >300c and<700 and >700 c | AB22: High energhy Discharge | AC22: =M22/H22 -> 1.08974359 | AD22: =IFERROR(P22/O22," ") -> 0.3333333333 | AE22: =P22/M22 -> 0.4152249135 | AF22: =IFERROR(N22/P22," ") -> 3 | AG22: =IF(AC22>1,"Thermal Decomposition, ",IF(AC22<0.1,"Corona,Arching")) -> Thermal Decomposition, | AH22: =IF(AD22<0.75,"Thermal Decomposition, ",IF(AD22>0.75,"Arching")) -> Thermal Decomposition, | AI22: =IF(AE22<0.3,"Thermal Decomposition,corona ",IF(AE22>0.3,"Arching")) -> Arching | AJ22: =IF(AF22>0.4,"Thermal Decomposition,corona ",IF(AF22<0.4,"Arching")) -> Thermal Decomposition,corona
A23: 21 | B23: 96591 | C23: 10 MVA | D23: 33/11 KV | E23: MARSONS | F23: 2015 | G23: 7.8 | H23: 9.594 | I23: 14803.152 | J23: 59331.48 | K23: 290.472 | L23: 2714.79 | M23: 17.784 | N23: 8 | O23: 7.722 | P23: 9 | Q23: =IFERROR(P23/O23," ") -> 1.165501166 | R23: =M23/H23 -> 1.853658537 | S23: =IFERROR(O23/N23," ") -> 0.96525 | T23: Arching | U23: =IF(R23>1,"Thermal Fault <700c, thermal fault >700c ") -> Thermal Fault <700c, thermal fault >700c | V23: =IF(S23<1,"Partial discharge, Normal ",IF(S23>3,"Arching,Thermal Fault > 700 c")) -> Partial discharge, Normal | W23: =P23/O23 -> 1.165501166 | X23: =IFERROR(M23/H23," ") -> 1.853658537 | Y23: =IFERROR(O23/N23," ") -> 0.96525 | Z23: =IF(W23>1,"Discharge of Low Energy, ",IF(W23<0.1,"Thermal Fault> 300c and<700 c")) -> Discharge of Low Energy, | AA23: =IF(X23<0.1,"Partial Discharges, ",IF(X23>1,"Thermal Fault >300c and<700 and >700 c")) -> Thermal Fault >300c and<700 and >700 c | AB23: High energhy Discharge | AC23: =M23/H23 -> 1.853658537 | AD23: =IFERROR(P23/O23," ") -> 1.165501166 | AE23: =P23/M23 -> 0.5060728745 | AF23: =IFERROR(N23/P23," ") -> 0.8888888889 | AG23: =IF(AC23>1,"Thermal Decomposition, ",IF(AC23<0.1,"Corona,Arching")) -> Thermal Decomposition, | AH23: =IF(AD23<0.75,"Thermal Decomposition, ",IF(AD23>0.75,"Arching")) -> Arching | AI23: =IF(AE23<0.3,"Thermal Decomposition,corona ",IF(AE23>0.3,"Arching")) -> Arching | AJ23: =IF(AF23>0.4,"Thermal Decomposition,corona ",IF(AF23<0.4,"Arching")) -> Thermal Decomposition,corona
A24: 22 | B24: 109394 | C24: 10 MVA | D24: 33/11 KV | E24: MARSONS | F24: 2020 | G24: 8.1 | H24: 2.106 | I24: 14994.639 | J24: 64523.304 | K24: 94.608 | L24: 898.047 | M24: 6 | N24: 7 | O24: 8 | P24: 10 | Q24: =IFERROR(P24/O24," ") -> 1.25 | R24: =M24/H24 -> 2.849002849 | S24: =IFERROR(O24/N24," ") -> 1.142857143 | T24: Arching | U24: =IF(R24<0.1, "Partial discharge", "Low temperature thermal ") -> Low temperature thermal | V24: Low Temprature thermal Fault,Thermal Fault<700c | W24: =P24/O24 -> 1.25 | X24: =IFERROR(M24/H24," ") -> 2.849002849 | Y24: =IFERROR(O24/N24," ") -> 1.142857143 | Z24: =IF(W24>1,"Discharge of Low Energy, ",IF(W24<0.1,"Thermal Fault> 300c and<700 c")) -> Discharge of Low Energy, | AA24: =IF(X24<0.1,"Partial Discharges, ",IF(X24>1,"Thermal Fault >300c and<700 and >700 c")) -> Thermal Fault >300c and<700 and >700 c | AB24: =IF(Y24<0.2,"Partial Discharges, ",IF(Y24>1,"Thermal Fault >700 c")) -> Thermal Fault >700 c | AC24: =M24/H24 -> 2.849002849 | AD24: =IFERROR(P24/O24," ") -> 1.25 | AE24: =P24/M24 -> 1.666666667 | AF24: =IFERROR(N24/P24," ") -> 0.7 | AG24: =IF(AC24>1,"Thermal Decomposition, ",IF(AC24<0.1,"Corona,Arching")) -> Thermal Decomposition, | AH24: =IF(AD24<0.75,"Thermal Decomposition, ",IF(AD24>0.75,"Arching")) -> Arching | AI24: =IF(AE24<0.3,"Thermal Decomposition,corona ",IF(AE24>0.3,"Arching")) -> Arching | AJ24: =IF(AF24>0.4,"Thermal Decomposition,corona ",IF(AF24<0.4,"Arching")) -> Thermal Decomposition,corona
A25: 23 | B25: 110120 | C25: 10 MVA | D25: 33/11 KV | E25: MARSONS | F25: 2020 | G25: 8.4 | H25: 3 | I25: 15372.084 | J25: 67096.092 | K25: 49.392 | L25: 558.768 | M25: 7 | N25: 6 | O25: 6 | P25: 34 | Q25: =IFERROR(P25/O25," ") -> 5.666666667 | R25: =M25/H25 -> 2.333333333 | S25: =IFERROR(O25/N25," ") -> 1 | T25: Arching | U25: =IF(R25>1,"Thermal Fault <700c, thermal fault >700c ") -> Thermal Fault <700c, thermal fault >700c | V25: Low Temprature thermal Fault,Thermal Fault<700c | W25: =P25/O25 -> 5.666666667 | X25: =IFERROR(M25/H25," ") -> 2.333333333 | Y25: =IFERROR(O25/N25," ") -> 1 | Z25: =IF(W25>1,"Discharge of Low Energy, ",IF(W25<0.1,"Thermal Fault> 300c and<700 c")) -> Discharge of Low Energy, | AA25: =IF(X25<0.1,"Partial Discharges, ",IF(X25>1,"Thermal Fault >300c and<700 and >700 c")) -> Thermal Fault >300c and<700 and >700 c | AB25: thermal fault <300 c | AC25: =M25/H25 -> 2.333333333 | AD25: =IFERROR(P25/O25," ") -> 5.666666667 | AE25: =P25/M25 -> 4.857142857 | AF25: =IFERROR(N25/P25," ") -> 0.1764705882 | AG25: =IF(AC25>1,"Thermal Decomposition, ",IF(AC25<0.1,"Corona,Arching")) -> Thermal Decomposition, | AH25: =IF(AD25<0.75,"Thermal Decomposition, ",IF(AD25>0.75,"Arching")) -> Arching | AI25: =IF(AE25<0.3,"Thermal Decomposition,corona ",IF(AE25>0.3,"Arching")) -> Arching | AJ25: =IF(AF25>0.4,"Thermal Decomposition,corona ",IF(AF25<0.4,"Arching")) -> Arching
A26: 24 | B26: 109392 | C26: 10 MVA | D26: 33/11 KV | E26: MARSONS | F26: 2020 | G26: 8.4 | H26: 3.948 | I26: 15735.972 | J26: 66306.156 | K26: 72.66 | L26: 751.884 | M26: 9 | N26: 11 | O26: 8 | P26: 17 | Q26: =IFERROR(P26/O26," ") -> 2.125 | R26: =M26/H26 -> 2.279635258 | S26: =IFERROR(O26/N26," ") -> 0.7272727273 | T26: Arching | U26: =IF(R26<0.1, "Partial discharge", "Low temperature thermal ") -> Low temperature thermal | V26: =IF(S26<1,"Partial discharge, Normal ",IF(S26>3,"Arching,Thermal Fault > 700 c")) -> Partial discharge, Normal | W26: =P26/O26 -> 2.125 | X26: =IFERROR(M26/H26," ") -> 2.279635258 | Y26: =IFERROR(O26/N26," ") -> 0.7272727273 | Z26: =IF(W26>1,"Discharge of Low Energy, ",IF(W26<0.1,"Thermal Fault> 300c and<700 c")) -> Discharge of Low Energy, | AA26: =IF(X26<0.1,"Partial Discharges, ",IF(X26>1,"Thermal Fault >300c and<700 and >700 c")) -> Thermal Fault >300c and<700 and >700 c | AB26: thermal fault <300 c | AC26: =M26/H26 -> 2.279635258 | AD26: =IFERROR(P26/O26," ") -> 2.125 | AE26: =P26/M26 -> 1.888888889 | AF26: =IFERROR(N26/P26," ") -> 0.6470588235 | AG26: =IF(AC26>1,"Thermal Decomposition, ",IF(AC26<0.1,"Corona,Arching")) -> Thermal Decomposition, | AH26: =IF(AD26<0.75,"Thermal Decomposition, ",IF(AD26>0.75,"Arching")) -> Arching | AI26: =IF(AE26<0.3,"Thermal Decomposition,corona ",IF(AE26>0.3,"Arching")) -> Arching | AJ26: =IF(AF26>0.4,"Thermal Decomposition,corona ",IF(AF26<0.4,"Arching")) -> Thermal Decomposition,corona
A27: 25 | B27: 109395 | C27: 10 MVA | D27: 33/11 KV | E27: MARSONS | F27: 2020 | G27: 8.2 | H27: 6 | I27: 14969.182 | J27: 65210.254 | K27: 76.67 | L27: 836.892 | M27: 5 | N27: 12 | O27: 6 | P27: 17 | Q27: =IFERROR(P27/O27," ") -> 2.833333333 | R27: =M27/H27 -> 0.8333333333 | S27: =IFERROR(O27/N27," ") -> 0.5 | T27: Arching | U27: Arching | V27: =IF(S27<1,"Partial discharge, Normal ",IF(S27>3,"Arching,Thermal Fault > 700 c")) -> Partial discharge, Normal | W27: =P27/O27 -> 2.833333333 | X27: =IFERROR(M27/H27," ") -> 0.8333333333 | Y27: =IFERROR(O27/N27," ") -> 0.5 | Z27: =IF(W27>1,"Discharge of Low Energy, ",IF(W27<0.1,"Thermal Fault> 300c and<700 c")) -> Discharge of Low Energy, | AA27: High Energy Discharge | AB27: thermal fault <300 c | AC27: =M27/H27 -> 0.8333333333 | AD27: =IFERROR(P27/O27," ") -> 2.833333333 | AE27: =P27/M27 -> 3.4 | AF27: =IFERROR(N27/P27," ") -> 0.7058823529 | AG27: Arching | AH27: =IF(AD27<0.75,"Thermal Decomposition, ",IF(AD27>0.75,"Arching")) -> Arching | AI27: =IF(AE27<0.3,"Thermal Decomposition,corona ",IF(AE27>0.3,"Arching")) -> Arching | AJ27: =IF(AF27>0.4,"Thermal Decomposition,corona ",IF(AF27<0.4,"Arching")) -> Thermal Decomposition,corona
A28: 26 | B28: 107358 | C28: 10 MVA | D28: 33/11 KV | E28: MARSONS | F28: 2019 | G28: 8 | H28: 7 | I28: 14494.72 | J28: 62801.68 | K28: 158.08 | L28: 1702.24 | M28: 3 | N28: 9 | O28: 8 | P28: 34 | Q28: =IFERROR(P28/O28," ") -> 4.25 | R28: =M28/H28 -> 0.4285714286 | S28: =IFERROR(O28/N28," ") -> 0.8888888889 | T28: Arching | U28: Arching | V28: =IF(S28<1,"Partial discharge, Normal ",IF(S28>3,"Arching,Thermal Fault > 700 c")) -> Partial discharge, Normal | W28: =P28/O28 -> 4.25 | X28: =IFERROR(M28/H28," ") -> 0.4285714286 | Y28: =IFERROR(O28/N28," ") -> 0.8888888889 | Z28: =IF(W28>1,"Discharge of Low Energy, ",IF(W28<0.1,"Thermal Fault> 300c and<700 c")) -> Discharge of Low Energy, | AA28: High Energy Discharge | AB28: thermal fault <300 c | AC28: =M28/H28 -> 0.4285714286 | AD28: =IFERROR(P28/O28," ") -> 4.25 | AE28: =P28/M28 -> 11.33333333 | AF28: =IFERROR(N28/P28," ") -> 0.2647058824 | AG28: Arching | AH28: =IF(AD28<0.75,"Thermal Decomposition, ",IF(AD28>0.75,"Arching")) -> Arching | AI28: =IF(AE28<0.3,"Thermal Decomposition,corona ",IF(AE28>0.3,"Arching")) -> Arching | AJ28: =IF(AF28>0.4,"Thermal Decomposition,corona ",IF(AF28<0.4,"Arching")) -> Arching
A29: 27 | B29: 109393 | C29: 10 MVA | D29: 33/11 KV | E29: MARSONS | F29: 2020 | G29: 8.3 | H29: 9 | I29: 15162.108 | J29: 66073.644 | K29: 79.763 | L29: 842.035 | M29: 9 | N29: 11 | O29: 7 | P29: 9 | Q29: =IFERROR(P29/O29," ") -> 1.285714286 | R29: =M29/H29 -> 1 | S29: =IFERROR(O29/N29," ") -> 0.6363636364 | T29: Arching | U29: Arching | V29: =IF(S29<1,"Partial discharge, Normal ",IF(S29>3,"Arching,Thermal Fault > 700 c")) -> Partial discharge, Normal | W29: =P29/O29 -> 1.285714286 | X29: =IFERROR(M29/H29," ") -> 1 | Y29: =IFERROR(O29/N29," ") -> 0.6363636364 | Z29: =IF(W29>1,"Discharge of Low Energy, ",IF(W29<0.1,"Thermal Fault> 300c and<700 c")) -> Discharge of Low Energy, | AA29: High Energy Discharge | AB29: thermal fault <300 c | AC29: =M29/H29 -> 1 | AD29: =IFERROR(P29/O29," ") -> 1.285714286 | AE29: =P29/M29 -> 1 | AF29: =IFERROR(N29/P29," ") -> 1.222222222 | AG29: Arching | AH29: =IF(AD29<0.75,"Thermal Decomposition, ",IF(AD29>0.75,"Arching")) -> Arching | AI29: =IF(AE29<0.3,"Thermal Decomposition,corona ",IF(AE29>0.3,"Arching")) -> Arching | AJ29: =IF(AF29>0.4,"Thermal Decomposition,corona ",IF(AF29<0.4,"Arching")) -> Thermal Decomposition,corona
A30: 28 | B30: 102145 | C30: 10 MVA | D30: 33/11 KV | E30: MARSONS | F30: 2017 | G30: 8.5 | H30: 3.74 | I30: 15646.29 | J30: 67067.635 | K30: 110.415 | L30: 933.64 | M30: 5.865 | N30: 14 | O30: 5 | P30: 12 | Q30: =IFERROR(P30/O30," ") -> 2.4 | R30: =M30/H30 -> 1.568181818 | S30: =IFERROR(O30/N30," ") -> 0.3571428571 | T30: Arching | U30: =IF(R30>1,"Thermal Fault <700c, thermal fault >700c ") -> Thermal Fault <700c, thermal fault >700c | V30: =IF(S30<1,"Partial discharge, Normal ",IF(S30>3,"Arching,Thermal Fault > 700 c")) -> Partial discharge, Normal | W30: =P30/O30 -> 2.4 | X30: =IFERROR(M30/H30," ") -> 1.568181818 | Y30: =IFERROR(O30/N30," ") -> 0.3571428571 | Z30: =IF(W30>1,"Discharge of Low Energy, ",IF(W30<0.1,"Thermal Fault> 300c and<700 c")) -> Discharge of Low Energy, | AA30: =IF(X30<0.1,"Partial Discharges, ",IF(X30>1,"Thermal Fault >300c and<700 and >700 c")) -> Thermal Fault >300c and<700 and >700 c | AB30: thermal fault <300 c | AC30: =M30/H30 -> 1.568181818 | AD30: =IFERROR(P30/O30," ") -> 2.4 | AE30: =P30/M30 -> 2.046035806 | AF30: =IFERROR(N30/P30," ") -> 1.166666667 | AG30: =IF(AC30>1,"Thermal Decomposition, ",IF(AC30<0.1,"Corona,Arching")) -> Thermal Decomposition, | AH30: =IF(AD30<0.75,"Thermal Decomposition, ",IF(AD30>0.75,"Arching")) -> Arching | AI30: =IF(AE30<0.3,"Thermal Decomposition,corona ",IF(AE30>0.3,"Arching")) -> Arching | AJ30: =IF(AF30>0.4,"Thermal Decomposition,corona ",IF(AF30<0.4,"Arching")) -> Thermal Decomposition,corona
A31: 29 | B31: 103754 | C31: 10 MVA | D31: 33/11 KV | E31: MARSONS | F31: 2018 | G31: 8.3 | H31: 12.948 | I31: 15300.469 | J31: 64967.752 | K31: 161.601 | L31: 1625.887 | M31: 4.067 | N31: 11 | O31: 7 | P31: 45 | Q31: =IFERROR(P31/O31," ") -> 6.428571429 | R31: =M31/H31 -> 0.3141025641 | S31: =IFERROR(O31/N31," ") -> 0.6363636364 | T31: Arching | U31: Arching,Low temprature thermal fault | V31: =IF(S31<1,"Partial discharge, Normal ",IF(S31>3,"Arching,Thermal Fault > 700 c")) -> Partial discharge, Normal | W31: =P31/O31 -> 6.428571429 | X31: =IFERROR(M31/H31," ") -> 0.3141025641 | Y31: =IFERROR(O31/N31," ") -> 0.6363636364 | Z31: =IF(W31>1,"Discharge of Low Energy, ",IF(W31<0.1,"Thermal Fault> 300c and<700 c")) -> Discharge of Low Energy, | AA31: High Energy Discharge | AB31: thermal fault <300 c | AC31: =M31/H31 -> 0.3141025641 | AD31: =IFERROR(P31/O31," ") -> 6.428571429 | AE31: =P31/M31 -> 11.06466683 | AF31: =IFERROR(N31/P31," ") -> 0.2444444444 | AG31: Arching | AH31: =IF(AD31<0.75,"Thermal Decomposition, ",IF(AD31>0.75,"Arching")) -> Arching | AI31: =IF(AE31<0.3,"Thermal Decomposition,corona ",IF(AE31>0.3,"Arching")) -> Arching | AJ31: =IF(AF31>0.4,"Thermal Decomposition,corona ",IF(AF31<0.4,"Arching")) -> Arching
A32: 30 | B32: 103756 | C32: 10 MVA | D32: 33/11 KV | E32: MARSONS | F32: 2019 | G32: 8.5 | H32: 16.83 | I32: 16032.615 | J32: 66596.565 | K32: 155.975 | L32: 1646.195 | M32: 9 | N32: 14 | O32: 9 | P32: 37 | Q32: =IFERROR(P32/O32," ") -> 4.111111111 | R32: =M32/H32 -> 0.5347593583 | S32: =IFERROR(O32/N32," ") -> 0.6428571429 | T32: Arching | U32: Arching,Low temprature thermal fault | V32: =IF(S32<1,"Partial discharge, Normal ",IF(S32>3,"Arching,Thermal Fault > 700 c")) -> Partial discharge, Normal | W32: =P32/O32 -> 4.111111111 | X32: =IFERROR(M32/H32," ") -> 0.5347593583 | Y32: =IFERROR(O32/N32," ") -> 0.6428571429 | Z32: =IF(W32>1,"Discharge of Low Energy, ",IF(W32<0.1,"Thermal Fault> 300c and<700 c")) -> Discharge of Low Energy, | AA32: High Energy Discharge | AB32: thermal fault <300 c | AC32: =M32/H32 -> 0.5347593583 | AD32: =IFERROR(P32/O32," ") -> 4.111111111 | AE32: =P32/M32 -> 4.111111111 | AF32: =IFERROR(N32/P32," ") -> 0.3783783784 | AG32: Arching | AH32: =IF(AD32<0.75,"Thermal Decomposition, ",IF(AD32>0.75,"Arching")) -> Arching | AI32: =IF(AE32<0.3,"Thermal Decomposition,corona ",IF(AE32>0.3,"Arching")) -> Arching | AJ32: =IF(AF32>0.4,"Thermal Decomposition,corona ",IF(AF32<0.4,"Arching")) -> Arching
A33: 31 | B33: 102147 | C33: 10 MVA | D33: 33/11 KV | E33: MARSONS | F33: 2017 | G33: 8.4 | H33: 8.316 | I33: 15461.796 | J33: 64806.084 | K33: 249.564 | L33: 2456.58 | M33: 8.232 | N33: 6.468 | O33: 5 | P33: 38 | Q33: =IFERROR(P33/O33," ") -> 7.6 | R33: =M33/H33 -> 0.9898989899 | S33: =IFERROR(O33/N33," ") -> 0.7730364873 | T33: Arching | U33: Arching,Low temprature thermal fault | V33: =IF(S33<1,"Partial discharge, Normal ",IF(S33>3,"Arching,Thermal Fault > 700 c")) -> Partial discharge, Normal | W33: =P33/O33 -> 7.6 | X33: =IFERROR(M33/H33," ") -> 0.9898989899 | Y33: =IFERROR(O33/N33," ") -> 0.7730364873 | Z33: =IF(W33>1,"Discharge of Low Energy, ",IF(W33<0.1,"Thermal Fault> 300c and<700 c")) -> Discharge of Low Energy, | AA33: High Energy Discharge | AB33: thermal fault <300 c | AC33: =M33/H33 -> 0.9898989899 | AD33: =IFERROR(P33/O33," ") -> 7.6 | AE33: =P33/M33 -> 4.616132167 | AF33: =IFERROR(N33/P33," ") -> 0.1702105263 | AG33: Arching | AH33: =IF(AD33<0.75,"Thermal Decomposition, ",IF(AD33>0.75,"Arching")) -> Arching | AI33: =IF(AE33<0.3,"Thermal Decomposition,corona ",IF(AE33>0.3,"Arching")) -> Arching | AJ33: =IF(AF33>0.4,"Thermal Decomposition,corona ",IF(AF33<0.4,"Arching")) -> Arching
A34: 32 | B34: 109620(TIT005184) | C34: 10 MVA | D34: 33/11 KV | E34: MARSONS | F34: 2021 | G34: 8.4 | H34: 3 | I34: 15346.716 | J34: 66991.848 | K34: 48.468 | L34: 544.572 | M34: 6 | N34: 13 | O34: 9 | P34: 9 | Q34: =IFERROR(P34/O34," ") -> 1 | R34: =M34/H34 -> 2 | S34: =IFERROR(O34/N34," ") -> 0.6923076923 | T34: Arching | U34: =IF(R34>1,"Thermal Fault <700c, thermal fault >700c ") -> Thermal Fault <700c, thermal fault >700c | V34: =IF(S34<1,"Partial discharge, Normal ",IF(S34>3,"Arching,Thermal Fault > 700 c")) -> Partial discharge, Normal | W34: =P34/O34 -> 1 | X34: =IFERROR(M34/H34," ") -> 2 | Y34: =IFERROR(O34/N34," ") -> 0.6923076923 | Z34: High Energy Discharge | AA34: =IF(X34<0.1,"Partial Discharges, ",IF(X34>1,"Thermal Fault >300c and<700 and >700 c")) -> Thermal Fault >300c and<700 and >700 c | AB34: thermal fault <300 c | AC34: =M34/H34 -> 2 | AD34: =IFERROR(P34/O34," ") -> 1 | AE34: =P34/M34 -> 1.5 | AF34: =IFERROR(N34/P34," ") -> 1.444444444 | AG34: =IF(AC34>1,"Thermal Decomposition, ",IF(AC34<0.1,"Corona,Arching")) -> Thermal Decomposition, | AH34: =IF(AD34<0.75,"Thermal Decomposition, ",IF(AD34>0.75,"Arching")) -> Arching | AI34: =IF(AE34<0.3,"Thermal Decomposition,corona ",IF(AE34>0.3,"Arching")) -> Arching | AJ34: =IF(AF34>0.4,"Thermal Decomposition,corona ",IF(AF34<0.4,"Arching")) -> Thermal Decomposition,corona
A35: 33 | B35: 109618(TIT005718) | C35: 10 MVA | D35: 33/11 KV | E35: MARSONS | F35: 2015 | G35: 8.3 | H35: 4.814 | I35: 15187.174 | J35: 62781.615 | K35: 375.492 | L35: 3515.548 | M35: 10.126 | N35: 8.217 | O35: 5 | P35: 2 | Q35: =IFERROR(P35/O35," ") -> 0.4 | R35: =M35/H35 -> 2.103448276 | S35: =IFERROR(O35/N35," ") -> 0.6084945844 | T35: =IF(Q35<1,"Partial discharge,Low Temprature thermal fault,") -> Partial discharge,Low Temprature thermal fault, | U35: =IF(R35>1,"Thermal Fault <700c, thermal fault >700c ") -> Thermal Fault <700c, thermal fault >700c | V35: =IF(S35<1,"Partial discharge, Normal ",IF(S35>3,"Arching,Thermal Fault > 700 c")) -> Partial discharge, Normal | W35: =P35/O35 -> 0.4 | X35: =IFERROR(M35/H35," ") -> 2.103448276 | Y35: =IFERROR(O35/N35," ") -> 0.6084945844 | Z35: High Energy Discharge | AA35: =IF(X35<0.1,"Partial Discharges, ",IF(X35>1,"Thermal Fault >300c and<700 and >700 c")) -> Thermal Fault >300c and<700 and >700 c | AB35: thermal fault <300 c | AC35: =M35/H35 -> 2.103448276 | AD35: =IFERROR(P35/O35," ") -> 0.4 | AE35: =P35/M35 -> 0.1975113569 | AF35: =IFERROR(N35/P35," ") -> 4.1085 | AG35: =IF(AC35>1,"Thermal Decomposition, ",IF(AC35<0.1,"Corona,Arching")) -> Thermal Decomposition, | AH35: =IF(AD35<0.75,"Thermal Decomposition, ",IF(AD35>0.75,"Arching")) -> Thermal Decomposition, | AI35: =IF(AE35<0.3,"Thermal Decomposition,corona ",IF(AE35>0.3,"Arching")) -> Thermal Decomposition,corona | AJ35: =IF(AF35>0.4,"Thermal Decomposition,corona ",IF(AF35<0.4,"Arching")) -> Thermal Decomposition,corona
A36: 34 | B36: 172827(DIT000018) | C36: 10 MVA | D36: 33/11 KV | E36: MARSONS | F36: 2021 | G36: 8.1 | H36: 7 | I36: 14919.633 | J36: 64300.473 | K36: 53.784 | L36: 547.965 | M36: 9 | N36: 9 | O36: 9 | P36: 56 | Q36: =IFERROR(P36/O36," ") -> 6.222222222 | R36: =M36/H36 -> 1.285714286 | S36: =IFERROR(O36/N36," ") -> 1 | T36: Arching | U36: =IF(R36>1,"Thermal Fault <700c, thermal fault >700c ") -> Thermal Fault <700c, thermal fault >700c | V36: Low Temprature thermal Fault,Thermal Fault<700c | W36: =P36/O36 -> 6.222222222 | X36: =IFERROR(M36/H36," ") -> 1.285714286 | Y36: =IFERROR(O36/N36," ") -> 1 | Z36: =IF(W36>1,"Discharge of Low Energy, ",IF(W36<0.1,"Thermal Fault> 300c and<700 c")) -> Discharge of Low Energy, | AA36: =IF(X36<0.1,"Partial Discharges, ",IF(X36>1,"Thermal Fault >300c and<700 and >700 c")) -> Thermal Fault >300c and<700 and >700 c | AB36: thermal fault <300 c | AC36: =M36/H36 -> 1.285714286 | AD36: =IFERROR(P36/O36," ") -> 6.222222222 | AE36: =P36/M36 -> 6.222222222 | AF36: =IFERROR(N36/P36," ") -> 0.1607142857 | AG36: =IF(AC36>1,"Thermal Decomposition, ",IF(AC36<0.1,"Corona,Arching")) -> Thermal Decomposition, | AH36: =IF(AD36<0.75,"Thermal Decomposition, ",IF(AD36>0.75,"Arching")) -> Arching | AI36: =IF(AE36<0.3,"Thermal Decomposition,corona ",IF(AE36>0.3,"Arching")) -> Arching | AJ36: =IF(AF36>0.4,"Thermal Decomposition,corona ",IF(AF36<0.4,"Arching")) -> Arching
A37: 35 | B37: 172827 | C37: 10 MVA | D37: 33/11 KV | E37: RAJASTAN | F37: 2008 | G37: 8.5 | H37: 8.415 | I37: 15806.6 | J37: 66676.55 | K37: 160.395 | L37: 1769.955 | M37: 5.355 | N37: 7 | O37: 5 | P37: 78 | Q37: =IFERROR(P37/O37," ") -> 15.6 | R37: =M37/H37 -> 0.6363636364 | S37: =IFERROR(O37/N37," ") -> 0.7142857143 | T37: Arching | U37: =IF(R37<0.1, "Partial discharge", "Low temperature thermal ") -> Low temperature thermal | V37: =IF(S37<1,"Partial discharge, Normal ",IF(S37>3,"Arching,Thermal Fault > 700 c")) -> Partial discharge, Normal | W37: =P37/O37 -> 15.6 | X37: =IFERROR(M37/H37," ") -> 0.6363636364 | Y37: =IFERROR(O37/N37," ") -> 0.7142857143 | Z37: =IF(W37>1,"Discharge of Low Energy, ",IF(W37<0.1,"Thermal Fault> 300c and<700 c")) -> Discharge of Low Energy, | AA37: High Energy Discharge | AB37: thermal fault <300 c | AC37: =M37/H37 -> 0.6363636364 | AD37: =IFERROR(P37/O37," ") -> 15.6 | AE37: =P37/M37 -> 14.56582633 | AF37: =IFERROR(N37/P37," ") -> 0.08974358974 | AG37: Arching | AH37: =IF(AD37<0.75,"Thermal Decomposition, ",IF(AD37>0.75,"Arching")) -> Arching | AI37: =IF(AE37<0.3,"Thermal Decomposition,corona ",IF(AE37>0.3,"Arching")) -> Arching | AJ37: =IF(AF37>0.4,"Thermal Decomposition,corona ",IF(AF37<0.4,"Arching")) -> Arching
A38: 36 | B38: 172583 | C38: 10 MVA | D38: 33/11 KV | E38: RAJASTAN | F38: 2006 | G38: 8.2 | H38: 5.084 | I38: 14945.648 | J38: 64417.806 | K38: 166.87 | L38: 1974.478 | M38: 5.166 | N38: 7.298 | O38: 3.69 | P38: 8 | Q38: =IFERROR(P38/O38," ") -> 2.16802168 | R38: =M38/H38 -> 1.016129032 | S38: =IFERROR(O38/N38," ") -> 0.5056179775 | T38: Arching | U38: =IF(R38>1,"Thermal Fault <700c, thermal fault >700c ") -> Thermal Fault <700c, thermal fault >700c | V38: =IF(S38<1,"Partial discharge, Normal ",IF(S38>3,"Arching,Thermal Fault > 700 c")) -> Partial discharge, Normal | W38: =P38/O38 -> 2.16802168 | X38: =IFERROR(M38/H38," ") -> 1.016129032 | Y38: =IFERROR(O38/N38," ") -> 0.5056179775 | Z38: =IF(W38>1,"Discharge of Low Energy, ",IF(W38<0.1,"Thermal Fault> 300c and<700 c")) -> Discharge of Low Energy, | AA38: =IF(X38<0.1,"Partial Discharges, ",IF(X38>1,"Thermal Fault >300c and<700 and >700 c")) -> Thermal Fault >300c and<700 and >700 c | AB38: thermal fault <300 c | AC38: =M38/H38 -> 1.016129032 | AD38: =IFERROR(P38/O38," ") -> 2.16802168 | AE38: =P38/M38 -> 1.548586914 | AF38: =IFERROR(N38/P38," ") -> 0.91225 | AG38: =IF(AC38>1,"Thermal Decomposition, ",IF(AC38<0.1,"Corona,Arching")) -> Thermal Decomposition, | AH38: =IF(AD38<0.75,"Thermal Decomposition, ",IF(AD38>0.75,"Arching")) -> Arching | AI38: =IF(AE38<0.3,"Thermal Decomposition,corona ",IF(AE38>0.3,"Arching")) -> Arching | AJ38: =IF(AF38>0.4,"Thermal Decomposition,corona ",IF(AF38<0.4,"Arching")) -> Thermal Decomposition,corona
A39: 37 | B39: 109617(TIT0057147) | C39: 10 MVA | D39: 33/11 KV | E39: MARSONS | F39: 2021 | G39: 8.5 | H39: 1.275 | I39: 15541.74 | J39: 67965.405 | K39: 63.665 | L39: 654.245 | M39: 9 | N39: 11 | O39: 5 | P39: 9 | Q39: =IFERROR(P39/O39," ") -> 1.8 | R39: =M39/H39 -> 7.058823529 | S39: =IFERROR(O39/N39," ") -> 0.4545454545 | T39: Arching | U39: =IF(R39<0.1, "Partial discharge", "Low temperature thermal ") -> Low temperature thermal | V39: =IF(S39<1,"Partial discharge, Normal ",IF(S39>3,"Arching,Thermal Fault > 700 c")) -> Partial discharge, Normal | W39: =P39/O39 -> 1.8 | X39: =IFERROR(M39/H39," ") -> 7.058823529 | Y39: =IFERROR(O39/N39," ") -> 0.4545454545 | Z39: =IF(W39>1,"Discharge of Low Energy, ",IF(W39<0.1,"Thermal Fault> 300c and<700 c")) -> Discharge of Low Energy, | AA39: =IF(X39<0.1,"Partial Discharges, ",IF(X39>1,"Thermal Fault >300c and<700 and >700 c")) -> Thermal Fault >300c and<700 and >700 c | AB39: thermal fault <300 c | AC39: =M39/H39 -> 7.058823529 | AD39: =IFERROR(P39/O39," ") -> 1.8 | AE39: =P39/M39 -> 1 | AF39: =IFERROR(N39/P39," ") -> 1.222222222 | AG39: =IF(AC39>1,"Thermal Decomposition, ",IF(AC39<0.1,"Corona,Arching")) -> Thermal Decomposition, | AH39: =IF(AD39<0.75,"Thermal Decomposition, ",IF(AD39>0.75,"Arching")) -> Arching | AI39: =IF(AE39<0.3,"Thermal Decomposition,corona ",IF(AE39>0.3,"Arching")) -> Arching | AJ39: =IF(AF39>0.4,"Thermal Decomposition,corona ",IF(AF39<0.4,"Arching")) -> Thermal Decomposition,corona
A40: 38 | B40: 172521(DIT000064) | C40: 10 MVA | D40: 33/11 | E40: RAJSTHAN TRANSFORMER | F40: 2006 | G40: 8.3 | H40: 7.968 | I40: 15116.126 | J40: 64924.011 | K40: 163.925 | L40: 1848.908 | M40: 7.968 | N40: 2.988 | O40: 7 | P40: 5 | Q40: =IFERROR(P40/O40," ") -> 0.7142857143 | R40: =M40/H40 -> 1 | S40: =IFERROR(O40/N40," ") -> 2.34270415 | T40: =IF(Q40<1,"Partial discharge,Low Temprature thermal fault,") -> Partial discharge,Low Temprature thermal fault, | U40: Arching,Low temprature thermal fault | V40: Low Temprature thermal Fault,Thermal Fault<700c | W40: =P40/O40 -> 0.7142857143 | X40: =IFERROR(M40/H40," ") -> 1 | Y40: =IFERROR(O40/N40," ") -> 2.34270415 | Z40: High Energy Discharge | AA40: High Energy Discharge | AB40: =IF(Y40<0.2,"Partial Discharges, ",IF(Y40>1,"Thermal Fault >700 c")) -> Thermal Fault >700 c | AC40: =M40/H40 -> 1 | AD40: =IFERROR(P40/O40," ") -> 0.7142857143 | AE40: =P40/M40 -> 0.6275100402 | AF40: =IFERROR(N40/P40," ") -> 0.5976 | AG40: Arching | AH40: =IF(AD40<0.75,"Thermal Decomposition, ",IF(AD40>0.75,"Arching")) -> Thermal Decomposition, | AI40: =IF(AE40<0.3,"Thermal Decomposition,corona ",IF(AE40>0.3,"Arching")) -> Arching | AJ40: =IF(AF40>0.4,"Thermal Decomposition,corona ",IF(AF40<0.4,"Arching")) -> Thermal Decomposition,corona
...

Sheet Sheet1
A1: DESCRIPTION OF DGA DATA | E1: DESCRIPTION OF DGA DATA | I1: DESCRIPTION OF DGA DATA
A2: Rogers Ratio Method | E2: IEC Ratio Method | I2: Dornenburg Ratio Method
A3: FAULT TYPE | B3: FAULT CODE | C3: NUMBER OF SAMPLES | E3: FAULT TYPE | F3: FAULT CODE | G3: NUMBER OF SAMPLES | I3: FAULT TYPE | J3: FAULT CODE | K3: NUMBER OF SAMPLES
C4: DATASET 1 | G4: DATASET 1 | K4: DATASET 1
A6: Arching | C6: =COUNTIF(DGA!T3:V512,"*Arching*") -> 607 | E6: Partial discharges | G6: =COUNTIF(DGA!AA2:AC512,"*Partial Discharges*") -> 14 | I6: Thermal Decomposition | K6: =COUNTIF(DGA!AG2:AJ512,"*Thermal Decomposition*") -> 853
A7: Partial discharge | C7: =COUNTIF(DGA!T3:V512,"*Partial discharge*") -> 461 | E7: Discharges of low energy | G7: =COUNTIF(DGA!Z2:AB512,"*Discharge of Low Energy*") -> 243 | I7: Corona | K7: =COUNTIF(DGA!AG2:AJ512,"*corona*") -> 459
A8: Low temperature thermal fault | C8: =COUNTIF(DGA!T3:V512,"*Low temprature thermal fault*") -> 632 | E8: High energy discharges | G8: =COUNTIF(DGA!Z2:AB514,"*High Energy Discharge*") -> 497 | I8: Arching | K8: =COUNTIF(DGA!AG2:AJ512,"*Arching*") -> 1179
A9: Thermal fault <700°C | C9: =COUNTIF(DGA!T2:V512,"*Thermal Fault <700c*") -> 177 | E9: Thermal faults<300°C | G9: =COUNTIF(DGA!Z2:AB512,"*Thermal Fault <F10300c*") -> 0
A10: Thermal fault >700°C | C10: =COUNTIF(DGA!T2:V512,"*Thermal Fault <700c*") -> 177 | E10: Thermal faults>300°C and <700°C | G10: =COUNTIF(DGA!Z2:AB512,"*Thermal Fault> 300c and<700 c*") -> 8
E11: Thermal faults>700°C | G11: =COUNTIF(DGA!Z2:AB512,"* >700 c*") -> 479
A12: Total | C12: =SUM(C6:C10) -> 2054 | E12: Total | G12: =SUM(G6:G11) -> 1241 | I12: Total | K12: =SUM(K6:K8) -> 2491
